<?xml version="1.0"?>
<sdf version='1.6'>
    <model name='hunter'>
      <link name="base_footprint"></link>
      <joint name="base_joint" type="fixed">
        <parent>base_footprint</parent>
        <child>base_link</child>
      </joint>
      <link name='base_link'>
        <pose frame=''>0 0 0 0 -0 0</pose>
        <inertial>
          <pose frame=''>0 -0 0 0 -0 0</pose>
          <mass>21.02945169536679</mass>
          <inertia>
            <ixx>0.0332370959804736</ixx>
            <ixy>-1.013150489971E-06</ixy>
            <ixz>-0.00188859201421112</ixz>
            <iyy>0.111072002332437</iyy>
            <iyz>-5.13308150598312E-07</iyz>
            <izz>0.12660862809283</izz>
          </inertia>
        </inertial>

        <collision name='base_link_collision'>
          <pose frame=''>0 0 0 0 -0 0</pose>
          <geometry>
            <mesh>
              <scale>1 1 1</scale>
              <uri>model://hunter/meshes/base_link.dae</uri>
            </mesh>
          </geometry>
        </collision>

        <visual name='base_link_visual'>
          <pose frame=''>0 0 0 0 -0 0</pose>
          <geometry>
            <mesh>
              <scale>1 1 1</scale>
              <uri>model://hunter/meshes/base_link.dae</uri>
            </mesh>
          </geometry>
        </visual>
      </link>

      <link name='front_steer_left_link'>
        <inertial>
          <pose frame=''>-0.012614 1.8116E-05 0.0023132 0 0 0</pose>
            <mass>7.8526</mass>
            <inertia>
              <ixx>0.063827</ixx>
              <ixy>0</ixy>
              <ixz>0</ixz>
              <iyy>0.063827</iyy>
              <iyz>0</iyz>
              <izz>0.11091</izz>
            </inertia>
        </inertial>
        <collision name='front_steer_left_link_collision'>
          <geometry>
            <cylinder>
              <length>0.001</length>
              <radius>0.005</radius>
            </cylinder>
          </geometry>
        </collision>
        <visual name='front_steer_left_link_visual'>
          <geometry>
            <cylinder>
              <length>0.001</length>
              <radius>0.005</radius>
            </cylinder>
          </geometry>
        </visual>
      </link>

      <joint name='front_steer_left_joint' type='revolute'>
        <pose>0.37142 0.29199 -0.1955 1.5708 0 0</pose>
        <parent>base_link</parent>
        <child>front_steer_left_link</child>
        <axis>
          <xyz>0 1 0</xyz>
          <limit>
            <lower>-0.69</lower>
            <upper>0.69</upper>
            <effort>0</effort>
            <velocity>0</velocity>
          </limit>
        </axis>
      <dynamics>
        <spring_reference>0</spring_reference>
        <spring_stiffness>0</spring_stiffness>
      </dynamics>
      <use_parent_model_frame>1</use_parent_model_frame>
      </joint>

      <link name='front_left_wheel_link'>
        <inertial>
            <pose>-6.5774E-06 2.0242E-05 -0.0096386 0 0 0</pose>
            <mass>7.7007</mass>

            <inertia>
              <ixx>0.063724</ixx>
              <ixy>0</ixy>
              <ixz>0</ixz>
              <iyy>0.063724</iyy>
              <iyz>0</iyz>
              <izz>0.11072</izz>
            </inertia>
        </inertial>
        <collision name='front_left_wheel_link_collision'>
          <pose frame=''>0 0 0 0 -0 0</pose>
          <geometry>
            <mesh>
              <scale>1 1 1</scale>
              <uri>model://hunter/meshes/front_left_wheel_link.dae</uri>
            </mesh>
          </geometry>
        </collision>
        <visual name='front_left_wheel_link_visual'>
          <pose frame=''>0 0 0 0 -0 0</pose>
          <geometry>
            <mesh>
              <scale>1 1 1</scale>
              <uri>model://hunter/meshes/front_left_wheel_link.dae</uri>
            </mesh>
          </geometry>
        </visual>
      </link>

    <joint name="front_left_wheel_joint" type="continuous">
      <parent>front_steer_left_link</parent>
      <child>front_left_wheel_link</child>
      <axis>
        <xyz>0 0 -1</xyz>
        <dynamics>
          <damping>0.0</damping>
          <friction>15</friction>
        </dynamics>
      </axis>
    </joint>

  <link name='front_steer_right_link'>
    <inertial>
        <pose>-8.9374E-08 1.0997E-07 0.0095958 0 0 0</pose>
        <mass>7.696</mass>
        <inertia>
          <ixx>0.063704</ixx>
          <ixy>0</ixy>
          <ixz>0</ixz>
          <iyy>0.063704</iyy>
          <iyz>0</iyz>
          <izz>0.11068</izz>
        </inertia>
    </inertial>
    <collision name='front_steer_right_link_collision'>
      <geometry>
        <cylinder>
          <length>0.001</length>
          <radius>0.005</radius>
        </cylinder>
      </geometry>
    </collision>
    <visual name='front_steer_right_link_visual'>
      <geometry>
        <cylinder>
          <length>0.001</length>
          <radius>0.005</radius>
        </cylinder>
      </geometry>
    </visual>
  </link>

      <joint name='front_steer_right_joint' type='revolute'>
        <pose>0.37142 -0.29201 -0.1955 1.5708 0 0</pose>
        <parent>base_link</parent>
        <child>front_steer_right_link</child>
        <axis>
          <xyz>0 1 0</xyz>
          <limit>
            <lower>-0.69</lower>
            <upper>0.69</upper>
            <effor>0</effor>
            <velocity>0</velocity>
          </limit>
        </axis>
      </joint>

      <link name='front_right_wheel_link'>
        <inertial>
            <pose>-9.1148E-08 1.1284E-07 0.0095049 0 0 0</pose>
            <mass>7.5613</mass>
            <inertia>
              <ixx>0.063626</ixx>
              <ixy>0</ixy>
              <ixz>0</ixz>
              <iyy>0.063626</iyy>
              <iyz>0</iyz>
              <izz>0.11054</izz>
            </inertia>
        </inertial>
        <collision name='front_right_wheel_link_collision'>
          <pose frame=''>0 0 0 0 -0 0</pose>
          <geometry>
            <mesh>
              <scale>1 1 1</scale>
              <uri>model://hunter/meshes/front_right_wheel_link.dae</uri>
            </mesh>
          </geometry>
        </collision>
        <visual name='front_right_wheel_link_visual'>
            <pose>0 0 0 0 3.14 0</pose>
          <geometry>
            <mesh>
              <scale>1 1 1</scale>
              <uri>model://hunter/meshes/front_right_wheel_link.dae</uri>
            </mesh>
          </geometry>
        </visual>
      </link>

      <joint name='front_right_wheel_joint' type='continuous'>
        <parent>front_steer_right_link</parent>
        <child>front_right_wheel_link</child>
        <axis>
          <xyz>0 0 -1</xyz>
          <dynamics>
            <damping>0.0</damping>
            <friction>15</friction>
          </dynamics>
        </axis>
      </joint>

      <link name='left_rear_link'>
        <inertial>
          <pose>-8.826E-05 6.4342E-05 -0.0096491 0 0 0</pose>
          <mass>7.6692</mass>
          <inertia>
            <ixx>0.063699</ixx>
            <ixy>0</ixy>
            <ixz>0</ixz>
            <iyy>0.063699</iyy>
            <iyz>0</iyz>
            <izz>0.11067</izz>
          </inertia>
        </inertial>
        <collision name='left_rear_link_collision'>
          <pose frame=''>0 0 0 0 -0 0</pose>
          <geometry>
            <mesh>
              <scale>1 1 1</scale>
              <uri>model://hunter/meshes/left_rear_link.dae</uri>
            </mesh>
          </geometry>
        </collision>
        <visual name='left_rear_link_visual'>
          <pose frame=''>0 0 0 0 -0 0</pose>
          <geometry>
            <mesh>
              <scale>1 1 1</scale>
              <uri>model://hunter/meshes/left_rear_link.dae</uri>
            </mesh>
          </geometry>
        </visual>
      </link>

      <joint name='left_rear_joint' type='continuous'>
        <pose>-0.28 0.29249 -0.19558 1.5708 0 0</pose>
        <parent>base_link</parent>
        <child>left_rear_link</child>
        <axis>
          <xyz>0 0 -1</xyz>
          <dynamics>
            <damping>0.0</damping>
            <friction>15</friction>
          </dynamics>
        </axis>
      </joint>

      <link name='right_rear_link'>
        <inertial>
            <pose>8.6344E-05 7.4488E-05 0.0097824 0 0 0</pose>
            <mass>7.7133</mass>
            <inertia>
              <ixx>0.06373</ixx>
              <ixy>0</ixy>
              <ixz>0</ixz>
              <iyy>0.06373</iyy>
              <iyz>0</iyz>
              <izz>0.11073</izz>
            </inertia>
        </inertial>
        <collision name='right_rear_link_collision'>
          <pose frame=''>0 0 0 0 -0 0</pose>
          <geometry>
            <mesh>
              <scale>1 1 1</scale>
              <uri>model://hunter/meshes/right_rear_link.dae</uri>
            </mesh>
          </geometry>
        </collision>
        <visual name='right_rear_link_visual'>
          <pose frame=''>0 0 0 0 -0 0</pose>
          <geometry>
            <mesh>
              <scale>1 1 1</scale>
              <uri>model://hunter/meshes/right_rear_link.dae</uri>
            </mesh>
          </geometry>
        </visual>
      </link>

      <joint name="right_rear_joint" type="continuous">
        <pose>-0.28018 -0.29251 -0.19558 1.5708 0.0026575 0</pose>
        <parent>base_link</parent>
        <child>right_rear_link</child>
        <axis>
          <xyz>0 0 -1</xyz>
          <dynamics>
            <damping>0.0</damping>
            <friction>15</friction>
          </dynamics>
        </axis>
    </joint>


    </model>
  </sdf>